Workbook

Sheet Form
B2: FORM NHẬP DỮ LIỆU
B4: DỮ LIỆU ỐNG GIÓ
B5: 1. Đường kính ống côn (mm)
B6: 2. Chiều dài ống gió tổn thất (mm)
B7: 3. Đường kính ống gió (mm)
B8: DỮ LIỆ̣U ĐỘNG CƠ
B9: 4. Công suất động cơ (kW)
B10: 5. Số vòng quay của quạt (vòng/phút)
B11: 6. Hệ số động cơ
B12: 7. Hiệu suất động cơ (%)
B13: DỮ LIỆU ĐO KIỂM
B14: 8. Áp suất khí quyển (kPa)
... B22: 16. Điện áp (V)

Sheet Calculation
A4: THÔNG SỐ ĐO KIỂM QUẠT CÔNG NGHIỆP
A5: I. Sơ đồ hệ thống đo kiểm
G9: Nhập
G11: Kết quả
A15: Sơ đồ quạt và vị trí đo kiểm
A17: II. Thông số cơ bản của đường ống và môi trường đo kiểm
A18: II.1 Thông số cơ bản của đường ống gió
A19: 1. Đường kính ống D5 (mm) | E19: 4. Tiết diện ống D5 (m²)
A20: 2. Chiều dài ống gió tổn thất L(mm) | E20: 5. Hệ số ma sát ống K
A21: 3. Đường kính ống gió D3 (mm) | E21: 6. Tiết diện ống gió D3(m²)
A22: II.2 Thông số cơ bản của quạt
A23: 7. Số vòng quay của quạt NLT (rpm) | E23: 11. Hiệu suất động cơ
A24: 8. Công suất động cơ (kW) | E24: 12. Độ nhớt không khí (Pa.s)
A25: 9. Hệ số động cơ | E25: 13. Áp suất khí quyển (kPa)
A26: 10. Tần số | E26: 14. Nhiệt độ làm việc (ºC)
A27: III. Thông số đo kiểm
A28: Kiểm tra số | C28: 1 | D28: 2 | E28: 3 | F28: 4 | G28: 5 | H28: 6 | I28: 7 | J28: 8 | K28: 9 | L28: 10
A29: Nhiệt độ bầu khô (ºC)
A30: Độ ẩm tương đối (%)
A31: Số vòng quay NTT (rpm)
A32: Chênh lệch áp suất (Pa)
A33: Áp suất tĩnh (Pa)
A34: Dòng làm việc (A)
A35: Điện áp (V)
A36: Tần số (Hz)
A40: III. Tính toán các thông số đo kiểm
A41: III.1 Kết quả tại điều kiện đo kiểm
A42: Bước | B42: STT | C42: 1 | D42: 2 | E42: 3 | F42: 4 | G42: 5 | H42: 6 | I42: 7 | J42: 8 | K42: 9 | L42: 10
A43: B1 | B43: Nhiệt độ bầu ướt (ºC)
A44: B2 | B44: Áp suất báo hòa Psat (Pa)
A45: B3 | B45: Áp suất riêng phần Pv
A46: B4 | B46: KLR môi trường (kg/m³)
A47: B5 | B47: Xác định RW
B48: Áp suất tại điểm đo chênh lệch áp suất P5
B49: KLR tại điểm đo lưu lượng PL5 (kg/m³)
B50: Độ nhớt không khí
A51: B6 | B51: Hệ số lưu lượng
A52: B7 | B52: Lưu lượng khối lượng (kg/s)
A53: B8 | B53: Lưu lượng thể tích (m³/s)
A54: B9 | B54: KLR điểm đo áp suất PL3 (kg/m³)
...

Sheet Report
D1: TOMECO MECHANIC-ELECTRICAL.,JSC
D2: Head Office: 53 Nguyen Xien Street, Thanh Xuan, Hanoi
D3: Factory: Km21+200 Ngoc Liep, Quoc Oai, Hanoi
D4: Tel: 0243 563 1130 - Fax: 0243 563 3980
D5: Email: toancau@tomeco.vn - Web: www.tomeco.vn
B12: BÁO CÁO KẾT QUẢ ĐO KIỂM ĐẶC TÍNH QUẠT CÔNG NGHIỆP
B13: Industrial Fan Performance Test Report
C15: Mã quạt/Model:
C17: Số phiếu đo/Report:
C19: Khách hàng/Customer:
C21: Dự án/Projetct:
C23: Ngày/Date:
C30: Người thực hiện:
C31: Test perfprmed by:
C33: Người chứng kiến:
C34: Test witnessed by:
C36: Người phê duyệt:
C37: Approved by:
B43: I. Tiêu chuẩn áp dụng/Reference Standard
B45: Đường đặc tuyến và các thông tin kỹ thuật của quạt được đo kiểm phù hợp tiêu chuẩn ISO 5801:2007 và TCVN 9439:2013
B46: The performance test and technical fans complies with ISO 5801:2007 and TCVN 9439:2013
B48: ISO 5801:2007 - Industrial Fans - Performance testing using Standardised airways
B49: TCVN 9439:2013 - Quạt công nghiệp - Thử đặc tính khi sử dụng đường ống gió tiêu chuẩn
B51: II. Thông tin quạt đo kiểm/Fan Details
C53: Mã quạt Model
C54: Kích thước guồng cánh (mm) Size (mm)
C55: Tốc độ (RPM) Speed (RPM)
C56: Kiểu truyền động Drive
C57: Công suất động cơ (kW) Output (kW)
B59: III. Sơ đồ hệ thống đo kiểm (Loại C)/Test arrangement (Type C)
B72: Hình 1. Sơ đồ kiểu lắp và vị trí đo kiểm
B73: Lưu ý:
B74: 1 - Nắn dòng
B75: 2 - Côn chuyển
B76: 3 - Vị trí lắp quạt
B79: IV. Dữ liệu đo kiểm/Test information
B82: Bảng 1. Thông số cơ bản của đường ống gió/Table 1. Duct information
B83: 1. Đường kính ống D5 (mm) 1. Duct diameter D5 (mm) | I83: =Calculation!D19 -> 0
B84: 2. Đường kính ống D3 (mm) 2. Duct diameter D3 (mm) | I84: =Calculation!D21 -> 0
B85: 3. Chiều dài tổn thất ống gió (mm) 3. Duct Friction Length (mm) | I85: =Calculation!D20 -> 0
...

Sheet Design Condition
A6: BÁO CÁO KẾT QUẢ ĐO KIỂM ĐẶC TÍNH QUẠT CÔNG NGHIỆP
A7: INDUSTRIAL FAN PERFORMANCE TEST REPORT
A8: Tiêu chuẩn áp dụng/Test standard: TCVN 9439:2013/ISO 5801:2007
A11: THÔNG TIN CHUNG / GENERAL INFORMATION
A12: Tên mẫu thử / Sample: | G12: Ngày nhận yêu cầu / Request date:
A13: Cơ sở sản xuất / Manufacturer: | G13: Ngày nhận mẫu / Reception date:
A14: Ký hiệu / Sample symbol. | G14: Ngày thử nghiệm / Test duration:
A15: Số lượng mẫu / Quantity: | G15: Ngày hoàn thành / Test completed:
A16: Tình trạng mẫu / Sample observation: | G16: Tiêu chuẩn áp dụng / Applied standards:
A18: THÔNG SỐ ĐO QUY ĐỔI VỀ ĐIỀU KIỆN THIẾT KẾ/TEST DATA AT DESIGN CONDITION
A19: Thông số/Parameters | C19: Đơn vị/Unit | D19: 1 | E19: 2 | F19: 3 | G19: 4 | H19: 5 | I19: 6 | J19: 7 | K19: 8 | L19: 9 | M19: 10
A20: Lưu lượng Air volume | C20: Am3/hr
A21: Áp suất tĩnh Static Pressure | C21: Pa
A22: Áp suất tổng Total Pressure | C22: Pa
A23: Công suất tiêu thụ Absorbed Power | C23: kW
A24: Hiệu suất tĩnh Static Effiency | C24: %
A25: Hiệu suất tổng Total Pressure | C25: %
A32: ĐẶC TUYẾN HOẠT ĐỘNG CỦA QUẠT / FAN PERFORMANCE CURVES
A71: KẾT LUẬN / FINAL INSPECTION REMARK
A75: Người thực hiện | F75: Người chứng kiến | K75: Phê duyệt
A76: Test performed by | F76: Test witnessed By | K76: Approved by

Sheet Normalized Condition
A6: BÁO CÁO KẾT QUẢ ĐO KIỂM ĐẶC TÍNH QUẠT CÔNG NGHIỆP
A7: INDUSTRIAL FAN PERFORMANCE TEST REPORT
A8: Tiêu chuẩn áp dụng/Test standard: TCVN 9439:2013/ISO 5801:2007
A11: THÔNG TIN CHUNG / GENERAL INFORMATION
A12: Tên mẫu thử / Sample: | G12: Ngày nhận yêu cầu / Request date:
A13: Cơ sở sản xuất / Manufacturer: | G13: Ngày nhận mẫu / Reception date:
A14: Ký hiệu / Sample symbol. | G14: Ngày thử nghiệm / Test duration:
A15: Số lượng mẫu / Quantity: | G15: Ngày hoàn thành / Test completed:
A16: Tình trạng mẫu / Sample observation: | G16: Tiêu chuẩn áp dụng / Applied standards:
A18: THÔNG SỐ ĐO QUY ĐỔI VỀ ĐIỀU KIỆN TIÊU CHUẨN/TEST DATA AT NORMALIZED CONDITION
A19: Thông số/Parameters | C19: Đơn vị/Unit | D19: 1 | E19: 2 | F19: 3 | G19: 4 | H19: 5 | I19: 6 | J19: 7 | K19: 8 | L19: 9 | M19: 10
A20: Lưu lượng Air volume | C20: Nm3/hr
A21: Áp suất tĩnh Static Pressure | C21: Pa
A22: Áp suất tổng Total Pressure | C22: Pa
A23: Công suất tiêu thụ Absorbed Power | C23: kW
A24: Hiệu suất tĩnh Static Effiency | C24: %
A25: Hiệu suất tổng Total Pressure | C25: %
A27: Lưu ý / Note:
A34: ĐẶC TUYẾN HOẠT ĐỘNG CỦA QUẠT / FAN PERFORMANCE CURVES
A73: KẾT LUẬN / FINAL INSPECTION REMARK
A77: Người thực hiện | F77: Người chứng kiến | K77: Phê duyệt
A78: Test performed by | F78: Test witnessed By | K78: Approved by

Sheet Operating Condition
A6: BÁO CÁO KẾT QUẢ ĐO KIỂM ĐẶC TÍNH QUẠT CÔNG NGHIỆP
A7: INDUSTRIAL FAN PERFORMANCE TEST REPORT
A8: Tiêu chuẩn áp dụng/Test standard: TCVN 9439:2013/ISO 5801:2007
A11: THÔNG TIN CHUNG / GENERAL INFORMATION
A12: Tên mẫu thử / Sample: | G12: Ngày nhận yêu cầu / Request date:
A13: Cơ sở sản xuất / Manufacturer: | G13: Ngày nhận mẫu / Reception date:
A14: Ký hiệu / Sample symbol. | G14: Ngày thử nghiệm / Test duration:
A15: Số lượng mẫu / Quantity: | G15: Ngày hoàn thành / Test completed:
A16: Tình trạng mẫu / Sample observation: | G16: Tiêu chuẩn áp dụng / Applied standards:
A18: THÔNG SỐ ĐO QUY ĐỔI VỀ ĐIỀU KIỆN LÀM VIỆC/TEST DATA AT OPERATION CONDITION
A19: Thông số/Parameters | C19: Đơn vị/Unit | D19: 1 | E19: 2 | F19: 3 | G19: 4 | H19: 5 | I19: 6 | J19: 7 | K19: 8 | L19: 9 | M19: 10
A20: Lưu lượng Air volume | C20: Am3/hr
A21: Áp suất tĩnh Static Pressure | C21: Pa
A22: Áp suất tổng Total Pressure | C22: Pa
A23: Công suất tiêu thụ Absorbed Power | C23: kW
A24: Hiệu suất tĩnh Static Effiency | C24: %
A25: Hiệu suất tổng Total Pressure | C25: %
A32: ĐẶC TUYẾN HOẠT ĐỘNG CỦA QUẠT / FAN PERFORMANCE CURVES
A71: KẾT LUẬN / FINAL INSPECTION REMARK
A75: Người thực hiện | F75: Người chứng kiến | K75: Phê duyệt
A76: Test performed by | F76: Test witnessed By | K76: Approved by

Sheet Full
A6: BÁO CÁO KẾT QUẢ ĐO KIỂM ĐẶC TÍNH QUẠT CÔNG NGHIỆP
A7: INDUSTRIAL FAN PERFORMANCE TEST REPORT
A8: Tiêu chuẩn áp dụng/Test standard: TCVN 9439:2013/ISO 5801:2007
A11: THÔNG TIN CHUNG / GENERAL INFORMATION
A12: Tên mẫu thử / Sample: | G12: Ngày nhận yêu cầu / Request date:
A13: Cơ sở sản xuất / Manufacturer: | G13: Ngày nhận mẫu / Reception date:
A14: Ký hiệu / Sample symbol. | G14: Ngày thử nghiệm / Test duration:
A15: Số lượng mẫu / Quantity: | G15: Ngày hoàn thành / Test completed:
A16: Tình trạng mẫu / Sample observation: | G16: Tiêu chuẩn áp dụng / Applied standards:
A18: THÔNG SỐ ĐO QUY ĐỔI VỀ ĐIỀU KIỆN THIẾT KẾ/TEST DATA AT DESIGN CONDITION
A19: Thông số/Parameters | C19: Đơn vị/Unit | D19: 1 | E19: 2 | F19: 3 | G19: 4 | H19: 5 | I19: 6 | J19: 7 | K19: 8 | L19: 9 | M19: 10
A20: Lưu lượng Air volume | C20: Am3/hr
A21: Áp suất tĩnh Static Pressure | C21: Pa
A22: Công suất tiêu thụ Absorbed Power | C22: kW
A23: Hiệu suất tĩnh Static Effiency | C23: %
A24: THÔNG SỐ ĐO QUY ĐỔI VỀ ĐIỀU TIÊU CHUẨN/TEST DATA AT NORMALIZED CONDITION
A25: Lưu lượng Air volume | C25: Nm3/hr
A26: Áp suất tĩnh Static Pressure | C26: Pa
A27: Công suất tiêu thụ Absorbed Power | C27: kW
A28: Hiệu suất tĩnh Static Effiency | C28: %
A29: THÔNG SỐ ĐO QUY ĐỔI VỀ ĐIỀU KIỆN LÀM VIỆC/TEST DATA AT OPERATING CONDITION
A30: Lưu lượng Air volume | C30: Am3/hr
A31: Áp suất tĩnh Static Pressure | C31: Pa
A32: Công suất tiêu thụ Absorbed Power | C32: kW
A33: Hiệu suất tĩnh Static Effiency | C33: %
A35: ĐẶC TUYẾN HOẠT ĐỘNG CỦA QUẠT / FAN PERFORMANCE CURVES
A71: KẾT LUẬN / FINAL INSPECTION REMARK
A75: Người thực hiện | F75: Người chứng kiến | K75: Phê duyệt
A76: Test performed by | F76: Test witnessed By | K76: Approved by

Sheet Sheet2
B3: Họp TOMECO về phần mềm C1
B4: Chậm trong chuyển đồi số
